<?xml version='1.0' encoding='utf-8'?>
<robot name="giraffe">
    <link name="gripper">
        <inertial>
            <origin xyz="-0.01860301090771668 -0.00569440975772796 -0.02499657686374647" rpy="0.0 -1.969704116134687e-29 -2.465190328815662e-32" />
            <mass value="0.12794799500230405" />
            <inertia ixx="2.6843989185106737e-05" iyy="4.098143182304979e-05" izz="2.3203463439812484e-05" ixy="6.263388610099874e-08" iyz="-6.738948397713716e-06" ixz="3.145210377249571e-07" />
        </inertial>
        <visual name="gripper_visual">
            <origin xyz="-1.536278619873599e-09 -3.1128798205770637e-09 3.772454633121925e-09" rpy="-0.007560605649348008 -0.19279245464075415 -1.5693537229972259" />
            <geometry>
                <mesh filename="meshes/gripper.stl" scale="0.001 0.001 0.001" />
            </geometry>
        </visual>
        <collision name="gripper_collision">
            <origin xyz="-1.536278619873599e-09 -3.1128798205770637e-09 3.772454633121925e-09" rpy="-0.007560605649348008 -0.19279245464075415 -1.5693537229972259" />
            <geometry>
                <mesh filename="meshes/gripper.stl" scale="0.001 0.001 0.001" />
            </geometry>
        </collision>
    </link>
    <link name="wrist_2">
        <inertial>
            <origin xyz="0.0004077168422306421 -0.022362358864649858 -0.0010846017595385771" rpy="0.0 -0.0 1.0587911840678754e-22" />
            <mass value="0.20479740953235626" />
            <inertia ixx="0.00010474486066780403" iyy="5.807508762734081e-05" izz="9.15769083376152e-05" ixy="3.7810798955409227e-08" iyz="2.107225246678346e-05" ixz="3.4354426532771305e-07" />
        </inertial>
        <visual name="wrist_2_visual">
            <origin xyz="-2.295511518646265e-09 -3.4905334800328094e-09 1.4340484533192921e-09" rpy="1.6786820342550084 -1.563326154608222 3.0270412523171335" />
            <geometry>
                <mesh filename="meshes/wrist_2.stl" scale="0.001 0.001 0.001" />
            </geometry>
        </visual>
        <collision name="wrist_2_collision">
            <origin xyz="-2.295511518646265e-09 -3.4905334800328094e-09 1.4340484533192921e-09" rpy="1.6786820342550084 -1.563326154608222 3.0270412523171335" />
            <geometry>
                <mesh filename="meshes/wrist_2.stl" scale="0.001 0.001 0.001" />
            </geometry>
        </collision>
    </link>
    <link name="wrist_1">
        <inertial>
            <origin xyz="0.02676902901195014 -0.00029662167561329334 -0.0195538415729843" rpy="0.0 -1.1498681155346105e-23 0.0" />
            <mass value="0.11585466541730426" />
            <inertia ixx="4.041104680803375e-05" iyy="7.006601712316438e-05" izz="4.0924310083948776e-05" ixy="1.189167076092873e-07" iyz="7.173420279061872e-08" ixz="-8.829515410226168e-06" />
        </inertial>
        <visual name="wrist_1_visual">
            <origin xyz="-4.87102305157805e-10 4.157872650623062e-09 -3.6338508113686885e-09" rpy="0.7853983074629309 1.569723427751906 -2.355435979599698" />
            <geometry>
                <mesh filename="meshes/wrist_1.stl" scale="0.001 0.001 0.001" />
            </geometry>
        </visual>
        <collision name="wrist_1_collision">
            <origin xyz="-4.87102305157805e-10 4.157872650623062e-09 -3.6338508113686885e-09" rpy="0.7853983074629309 1.569723427751906 -2.355435979599698" />
            <geometry>
                <mesh filename="meshes/wrist_1.stl" scale="0.001 0.001 0.001" />
            </geometry>
        </collision>
    </link>
    <link name="elbow">
        <inertial>
            <origin xyz="0.06237944456851811 0.0019142104459731525 0.01803922709743618" rpy="0.0 1.1766058613714266e-23 -2.5849394142282115e-26" />
            <mass value="0.34073484673669374" />
            <inertia ixx="9.627546814457547e-05" iyy="0.00044247288517526616" izz="0.0004172891788934109" ixy="-2.3174592329733838e-06" iyz="-8.836773082871546e-08" ixz="7.565208460403209e-06" />
        </inertial>
        <visual name="elbow_visual">
            <origin xyz="5.576150563513238e-10 4.455969300209972e-09 8.528574313437787e-10" rpy="-3.1415926535016943 1.5700376725697356 -1.5715549808826397" />
            <geometry>
                <mesh filename="meshes/elbow.stl" scale="0.001 0.001 0.001" />
            </geometry>
        </visual>
        <collision name="elbow_collision">
            <origin xyz="5.576150563513238e-10 4.455969300209972e-09 8.528574313437787e-10" rpy="-3.1415926535016943 1.5700376725697356 -1.5715549808826397" />
            <geometry>
                <mesh filename="meshes/elbow.stl" scale="0.001 0.001 0.001" />
            </geometry>
        </collision>
    </link>
    <link name="shoulder_lift">
        <inertial>
            <origin xyz="0.06764192057966556 -0.002421436223693716 0.019050024374668434" rpy="-2.5243548967072383e-29 -3.242736344388857e-23 -2.584939414228212e-26" />
            <mass value="0.34405090664671145" />
            <inertia ixx="8.610561790033238e-05" iyy="0.0004865862956736078" izz="0.0004687923504403828" ixy="-1.4792626013472515e-05" iyz="1.1414497814750369e-06" ixz="8.768882978819484e-06" />
        </inertial>
        <visual name="shoulder_lift_visual">
            <origin xyz="-4.445312229428566e-09 2.8085700343183364e-09 -4.691938313428068e-09" rpy="-0.0007586546387046919 1.5707963267945886 0" />
            <geometry>
                <mesh filename="meshes/shoulder_lift.stl" scale="0.001 0.001 0.001" />
            </geometry>
        </visual>
        <collision name="shoulder_lift_collision">
            <origin xyz="-4.445312229428566e-09 2.8085700343183364e-09 -4.691938313428068e-09" rpy="-0.0007586546387046919 1.5707963267945886 0" />
            <geometry>
                <mesh filename="meshes/shoulder_lift.stl" scale="0.001 0.001 0.001" />
            </geometry>
        </collision>
    </link>
    <link name="shoulder_pan">
        <inertial>
            <origin xyz="0.00016505484102978654 0.01901307107841664 -0.03152457767645542" rpy="0.0 -0.0 0.0" />
            <mass value="0.25023361974615993" />
            <inertia ixx="0.0001681257209623935" iyy="0.00012640162208110337" izz="8.317907613132334e-05" ixy="6.934136730131154e-08" iyz="-2.003213413013423e-05" ixz="6.092743286840859e-07" />
        </inertial>
        <visual name="shoulder_pan_visual">
            <origin xyz="2.0221776957270176e-09 1.6467048775774261e-10 -9.145601254090252e-10" rpy="3.1408339995829038 -5.755561313531633e-07 -3.14159265337143" />
            <geometry>
                <mesh filename="meshes/shoulder_pan.stl" scale="0.001 0.001 0.001" />
            </geometry>
        </visual>
        <collision name="shoulder_pan_collision">
            <origin xyz="2.0221776957270176e-09 1.6467048775774261e-10 -9.145601254090252e-10" rpy="3.1408339995829038 -5.755561313531633e-07 -3.14159265337143" />
            <geometry>
                <mesh filename="meshes/shoulder_pan.stl" scale="0.001 0.001 0.001" />
            </geometry>
        </collision>
    </link>
    <link name="base_link">
        <inertial>
            <origin xyz="-0.05011933435802444 7.711750237285299e-06 0.013957019259338604" rpy="0.0 0.0 0.0" />
            <mass value="0.8122108919622884" />
            <inertia ixx="0.0004009985014579228" iyy="0.0008345308392073704" izz="0.0009101655023903436" ixy="6.247300282676605e-07" iyz="3.222335785935421e-07" ixz="-8.116134483539433e-05" />
        </inertial>
        <visual name="base_link_visual">
            <origin xyz="0.0 0.0 0.0" rpy="0.0 0.0 0.0" />
            <geometry>
                <mesh filename="meshes/base_link.stl" scale="0.001 0.001 0.001" />
            </geometry>
        </visual>
        <collision name="base_link_collision">
            <origin xyz="0.0 0.0 0.0" rpy="0.0 0.0 0.0" />
            <geometry>
                <mesh filename="meshes/base_link.stl" scale="0.001 0.001 0.001" />
            </geometry>
        </collision>
    </link>
    <joint name="shoulder_lift_elbow_joint" type="revolute">
        <origin xyz="0.10947230258306867 0.025279000022638557 0.03678740220353282" rpy="3.1415926535895418 -3.694418900791045e-14 3.312801036938606e-10" />
        <parent link="shoulder_lift" />
        <child link="elbow" />
        <axis xyz="-6.536117188437661e-07 -0.000758999999905602 -0.9999992872820326" />
        <limit lower="0.0" upper="3.141593" effort="1000000" velocity="1000000" />
    </joint>
    <joint name="elbow_wrist_1_joint" type="revolute">
        <origin xyz="0.12026183003074924 0.002124210014976935 -0.00046737727122078134" rpy="-3.1415926535896053 -3.2273229239573103e-14 2.4764813144400373e-10" />
        <parent link="elbow" />
        <child link="wrist_1" />
        <axis xyz="0.000758346169637338 0.0007590000001867616 0.999999863100534" />
        <limit lower="-1.570796" upper="1.570796" effort="1000000" velocity="1000000" />
    </joint>
    <joint name="wrist_1_wrist_2_joint" type="revolute">
        <origin xyz="0.0603181067045017 -0.00017376999257662896 -0.02716566723557007" rpy="-3.049102007927164 1.5625820319968764 -1.4783560893203032" />
        <parent link="wrist_1" />
        <child link="wrist_2" />
        <axis xyz="-0.006668805523688299 -0.999976960468889 0.0008047864868520909" />
        <limit lower="-3.141593" upper="3.141593" effort="1000000" velocity="1000000" />
    </joint>
    <joint name="wrist_2_gripper_joint" type="revolute">
        <origin xyz="0.019497289303155634 -0.01740085346148174 -0.025281061620179096" rpy="-1.5708498378135036 -0.008179184380179302 0.00075867960162472" />
        <parent link="wrist_2" />
        <child link="gripper" />
        <axis xyz="0.9999726580742655 -6.000000001073452e-06 -0.007420635544791427" />
        <limit lower="0.0" upper="1.570796" effort="1000000" velocity="1000000" />
    </joint>
    <joint name="shoulder_pan_shoulder_lift_joint" type="revolute">
        <origin xyz="-0.018324870000000392 0.025746959999999867 -0.054606550000000066" rpy="1.5707963267950535 2.067468172103282e-10 1.57155498102004" />
        <parent link="shoulder_pan" />
        <child link="shoulder_lift" />
        <axis xyz="-3.456292077591485e-07 -1.5691907467237958e-13 -1.0000002880403989" />
        <limit lower="0.0" upper="1.570796" effort="1000000" velocity="1000000" />
    </joint>
    <joint name="base_link_shoulder_pan_joint" type="revolute">
        <origin xyz="-7.78471460176888e-06 -2.200004287780052e-05 0.017299999085318825" rpy="3.140833999582908 5.755561288912283e-07 1.5707963265766136" />
        <parent link="base_link" />
        <child link="shoulder_pan" />
        <axis xyz="1e-06 -0.000758999999997622 1.0" />
        <limit lower="-1.570796" upper="1.570796" effort="1000000" velocity="1000000" />
    </joint>
</robot>