<?xml version='1.0' encoding='utf-8'?>
<robot name="giraffe">
    <link name="gripper">
        <inertial>
            <origin xyz="-0.025000892830002997 -0.005661326825015313 0.018607312181508972" rpy="0.0 -1.9697039432292107e-29 0.0" />
            <mass value="0.12794799500230405" />
            <inertia ixx="2.319324861260159e-05" iyy="4.099154383467929e-05" izz="2.684409200068261e-05" ixy="-6.7256900280035665e-06" iyz="-7.31283595576902e-08" ixz="-3.0946608105867255e-07" />
        </inertial>
        <visual name="gripper_visual">
            <origin xyz="6.979771427495507e-10 -4.6217136784321157e-10 2.466540327539235e-09" rpy="-1.578225322507332 0.000671167992734743 -1.3787624817981818" />
            <geometry>
                <mesh filename="meshes/gripper.stl" scale="0.001 0.001 0.001" />
            </geometry>
        </visual>
        <collision name="gripper_collision">
            <origin xyz="6.979771427495507e-10 -4.6217136784321157e-10 2.466540327539235e-09" rpy="-1.578225322507332 0.000671167992734743 -1.3787624817981818" />
            <geometry>
                <mesh filename="meshes/gripper.stl" scale="0.001 0.001 0.001" />
            </geometry>
        </collision>
    </link>
    <link name="wrist_2">
        <inertial>
            <origin xyz="-0.022351676484507338 -0.00039972138547378355 -0.0012884749486257886" rpy="0.0 1.734723475976807e-18 -5.293955920339377e-23" />
            <mass value="0.20479740953235626" />
            <inertia ixx="5.7699127901001785e-05" iyy="0.00010474921073853709" izz="9.194851799325156e-05" ixy="-1.9100022560633366e-07" iyz="-2.481246577132945e-07" ixz="2.076701431003268e-05" />
        </inertial>
        <visual name="wrist_2_visual">
            <origin xyz="3.2248612313878766e-09 3.577125258225067e-09 1.2774515756319716e-09" rpy="-0.0008359974472397887 -1.5626642717606654 3.1357665419891942" />
            <geometry>
                <mesh filename="meshes/wrist_2.stl" scale="0.001 0.001 0.001" />
            </geometry>
        </visual>
        <collision name="wrist_2_collision">
            <origin xyz="3.2248612313878766e-09 3.577125258225067e-09 1.2774515756319716e-09" rpy="-0.0008359974472397887 -1.5626642717606654 3.1357665419891942" />
            <geometry>
                <mesh filename="meshes/wrist_2.stl" scale="0.001 0.001 0.001" />
            </geometry>
        </collision>
    </link>
    <link name="wrist_1">
        <inertial>
            <origin xyz="0.019554076475078137 -0.0003021044061850109 0.026768798858207887" rpy="0.0 -1.1498681155338425e-23 -2.5849394142282115e-26" />
            <mass value="0.11585466541730426" />
            <inertia ixx="4.09244458631439e-05" iyy="7.006568384257175e-05" izz="4.041124430942418e-05" ixy="-1.0054096592547805e-07" iyz="1.4811289997317556e-07" ixz="8.829348622233984e-06" />
        </inertial>
        <visual name="wrist_1_visual">
            <origin xyz="3.7196369406800047e-09 -4.913346405288621e-09 2.09915523186055e-09" rpy="-3.1415926535489875 0.0007586542251126293 1.2309512232619556e-10" />
            <geometry>
                <mesh filename="meshes/wrist_1.stl" scale="0.001 0.001 0.001" />
            </geometry>
        </visual>
        <collision name="wrist_1_collision">
            <origin xyz="3.7196369406800047e-09 -4.913346405288621e-09 2.09915523186055e-09" rpy="-3.1415926535489875 0.0007586542251126293 1.2309512232619556e-10" />
            <geometry>
                <mesh filename="meshes/wrist_1.stl" scale="0.001 0.001 0.001" />
            </geometry>
        </collision>
    </link>
    <link name="elbow">
        <inertial>
            <origin xyz="0.018040710480080404 0.001947846823969659 -0.062377974401196086" rpy="1.262177448353619e-29 1.084319833196823e-19 0.0" />
            <mass value="0.34073484673669374" />
            <inertia ixx="0.0004172890680133026" iyy="0.0004424692805008294" izz="9.627918369910404e-05" ixy="-6.352533852493458e-08" iyz="2.585839237231257e-06" ixz="-7.563313743043246e-06" />
        </inertial>
        <visual name="elbow_visual">
            <origin xyz="1.3042685886865968e-09 3.0645027138120898e-09 -5.618098697368624e-10" rpy="1.5707963268770082 9.594213444546337e-15 -3.141592653465207" />
            <geometry>
                <mesh filename="meshes/elbow.stl" scale="0.001 0.001 0.001" />
            </geometry>
        </visual>
        <collision name="elbow_collision">
            <origin xyz="1.3042685886865968e-09 3.0645027138120898e-09 -5.618098697368624e-10" rpy="1.5707963268770082 9.594213444546337e-15 -3.141592653465207" />
            <geometry>
                <mesh filename="meshes/elbow.stl" scale="0.001 0.001 0.001" />
            </geometry>
        </collision>
    </link>
    <link name="shoulder_lift">
        <inertial>
            <origin xyz="-0.019048152599260244 -0.0024872075879928614 0.06764007307782165" rpy="-2.5243548967072383e-29 -3.242736342201527e-23 -2.584939414228212e-26" />
            <mass value="0.34405090664671145" />
            <inertia ixx="0.0004687940825313238" iyy="0.0004866067780573811" izz="8.608340342561145e-05" ixy="-1.148311898754858e-06" iyz="-1.4495431697821775e-05" ixz="-8.75875191930491e-06" />
        </inertial>
        <visual name="shoulder_lift_visual">
            <origin xyz="-4.981332173414898e-09 -7.353014996880347e-10 4.553996260092674e-09" rpy="-2.0689865094233e-10 3.4897162989382564e-14 0.0007586544318003198" />
            <geometry>
                <mesh filename="meshes/shoulder_lift.stl" scale="0.001 0.001 0.001" />
            </geometry>
        </visual>
        <collision name="shoulder_lift_collision">
            <origin xyz="-4.981332173414898e-09 -7.353014996880347e-10 4.553996260092674e-09" rpy="-2.0689865094233e-10 3.4897162989382564e-14 0.0007586544318003198" />
            <geometry>
                <mesh filename="meshes/shoulder_lift.stl" scale="0.001 0.001 0.001" />
            </geometry>
        </collision>
    </link>
    <link name="shoulder_pan">
        <inertial>
            <origin xyz="0.018989126537816845 -0.00014114100724458572 -0.03153911875888037" rpy="3.944304526105059e-31 -0.0 0.0" />
            <mass value="0.25023361974615993" />
            <inertia ixx="0.0001263711792011625" iyy="0.00016812659583754895" izz="8.320864413610897e-05" ixy="-5.459311909927509e-08" iyz="-5.448476887045016e-07" ixz="-2.0064974009337587e-05" />
        </inertial>
        <visual name="shoulder_pan_visual">
            <origin xyz="-4.5077418817096596e-09 2.7279624843909097e-09 2.6181166790095743e-10" rpy="-3.141592078033501 -0.0007586540068868983 1.5707963265766112" />
            <geometry>
                <mesh filename="meshes/shoulder_pan.stl" scale="0.001 0.001 0.001" />
            </geometry>
        </visual>
        <collision name="shoulder_pan_collision">
            <origin xyz="-4.5077418817096596e-09 2.7279624843909097e-09 2.6181166790095743e-10" rpy="-3.141592078033501 -0.0007586540068868983 1.5707963265766112" />
            <geometry>
                <mesh filename="meshes/shoulder_pan.stl" scale="0.001 0.001 0.001" />
            </geometry>
        </collision>
    </link>
    <link name="base_link">
        <inertial>
            <origin xyz="-0.04766933435564214 7.711750237378191e-06 0.01395701925933853" rpy="0.0 0.0 0.0" />
            <mass value="0.812210891962288" />
            <inertia ixx="0.00040099850145792495" iyy="0.0008345308393965871" izz="0.0009101655025795578" ixy="6.24730028276225e-07" iyz="3.2223357859374003e-07" ixz="-8.116134480838747e-05" />
        </inertial>
        <visual name="base_link_visual">
            <origin xyz="0.0 0.0 0.0" rpy="0.0 0.0 0.0" />
            <geometry>
                <mesh filename="meshes/base_link.stl" scale="0.001 0.001 0.001" />
            </geometry>
        </visual>
        <collision name="base_link_collision">
            <origin xyz="0.0 0.0 0.0" rpy="0.0 0.0 0.0" />
            <geometry>
                <mesh filename="meshes/base_link.stl" scale="0.001 0.001 0.001" />
            </geometry>
        </collision>
    </link>
    <joint name="base_link_shoulder_pan_joint" type="revolute">
        <origin xyz="0.0024422199571167862 -2.1995292539264472e-05 0.017300000259741807" rpy="3.140833999582909 5.755561299100456e-07 -2.1828320944785756e-10" />
        <parent link="base_link" />
        <child link="shoulder_pan" />
        <axis xyz="1.0000000000000002e-06 -0.0007589999999976223 1.0000000000000002" />
        <limit lower="-1.570796" upper="1.570796" effort="1000000" velocity="1000000" />
    </joint>
    <joint name="shoulder_lift_elbow_joint" type="revolute">
        <origin xyz="-0.03680651674664366 0.02516801999240762 0.10949145809248002" rpy="3.1415926535895418 -3.694418900791044e-14 3.312801036937707e-10" />
        <parent link="shoulder_lift" />
        <child link="elbow" />
        <axis xyz="-1.000000288040399 -1.245357002589312e-10 -3.4562924470333753e-07" />
        <limit lower="0.0" upper="3.141593" effort="1000000" velocity="1000000" />
    </joint>
    <joint name="elbow_wrist_1_joint" type="revolute">
        <origin xyz="-0.0004656960202010452 0.0022157899999533637 -0.12026018130602735" rpy="-3.1415926535896053 -3.2273446080007626e-14 2.476481313354115e-10" />
        <parent link="elbow" />
        <child link="wrist_1" />
        <axis xyz="-0.9999998631005341 -1.23112379231774e-10 0.0007583461697307803" />
        <limit lower="-1.570796" upper="1.570796" effort="1000000" velocity="1000000" />
    </joint>
    <joint name="wrist_1_wrist_2_joint" type="revolute">
        <origin xyz="0.02716582734176012 -0.0001989299966499214 0.06031796682590525" rpy="-3.049102007927164 1.5625820319968764 -1.478356089320303" />
        <parent link="wrist_1" />
        <child link="wrist_2" />
        <axis xyz="-0.9999449329225374 0.006662002215913354 -0.008132268196377131" />
        <limit lower="-3.141593" upper="3.141593" effort="1000000" velocity="1000000" />
    </joint>
    <joint name="wrist_2_gripper_joint" type="revolute">
        <origin xyz="-0.017171676526959844 -0.019310353391698006 -0.025579471562416866" rpy="-1.5708498378135036 -0.0081791843801793 0.0007586796016247202" />
        <parent link="wrist_2" />
        <child link="gripper" />
        <axis xyz="-0.007420635544791429 -0.0007590000001611273 -0.9999726580742653" />
        <limit lower="0.0" upper="1.570796" effort="1000000" velocity="1000000" />
    </joint>
    <joint name="shoulder_pan_shoulder_lift_joint" type="revolute">
        <origin xyz="0.02570547999999961 0.018366289999999865 -0.05461217000000003" rpy="1.5707963267950535 2.0674681721032812e-10 1.57155498102004" />
        <parent link="shoulder_pan" />
        <child link="shoulder_lift" />
        <axis xyz="0.9999992880405297 0.0007590002067442921 -3.4638786203060774e-07" />
        <limit lower="0.0" upper="1.570796" effort="1000000" velocity="1000000" />
    </joint>
</robot>