<?xml version='1.0' encoding='utf-8'?>
<robot name="giraffe">
    <link name="gripper">
        <inertial>
            <origin xyz="-0.02497798710238577 -0.005761843912934932 0.018607218452251623" rpy="0.0 1.1929936094967745e-44 0.0" />
            <mass value="0.12794799500230522" />
            <inertia ixx="2.3247338577105056e-05" iyy="4.0937456356485144e-05" izz="2.6844089514527778e-05" ixy="-6.796661093000089e-06" iyz="-7.392638541311712e-08" ixz="-3.09361655686259e-07" />
        </inertial>
        <visual name="gripper_visual">
            <origin xyz="-0.003971177475340681 0.03088078780519652 0.28547247761430333" rpy="-1.5782225782968735 0.0007008802619671466 -1.3747623208876654" />
            <geometry>
                <mesh filename="meshes/gripper.stl" scale="0.001 0.001 0.001" />
            </geometry>
        </visual>
        <collision name="gripper_collision">
            <origin xyz="-0.003971177475340681 0.03088078780519652 0.28547247761430333" rpy="-1.5782225782968735 0.0007008802619671466 -1.3747623208876654" />
            <geometry>
                <mesh filename="meshes/gripper.stl" scale="0.001 0.001 0.001" />
            </geometry>
        </collision>
    </link>
    <link name="wrist_2">
        <inertial>
            <origin xyz="-0.022351684471092596 -0.00039972229811224835 -0.0012884720564361096" rpy="0.0 -0.0 0.0" />
            <mass value="0.20479740953235442" />
            <inertia ixx="5.769908906339316e-05" iyy="0.00010474921082978962" izz="9.194847985802965e-05" ixy="-1.9100005870670773e-07" iyz="-2.481280771598333e-07" ixz="2.0767014269064493e-05" />
        </inertial>
        <visual name="wrist_2_visual">
            <origin xyz="-0.021354220068846387 0.22060978636783563 -0.020899058488650795" rpy="-0.000835997494850449 -1.5626642716784576 3.135766542036777" />
            <geometry>
                <mesh filename="meshes/wrist_2.stl" scale="0.001 0.001 0.001" />
            </geometry>
        </visual>
        <collision name="wrist_2_collision">
            <origin xyz="-0.021354220068846387 0.22060978636783563 -0.020899058488650795" rpy="-0.000835997494850449 -1.5626642716784576 3.135766542036777" />
            <geometry>
                <mesh filename="meshes/wrist_2.stl" scale="0.001 0.001 0.001" />
            </geometry>
        </collision>
    </link>
    <link name="wrist_1">
        <inertial>
            <origin xyz="0.01955407643754404 -0.0003021014627924501 0.026768796444665812" rpy="-1.2621774483536192e-29 -1.1498681155338422e-23 -2.584939414228212e-26" />
            <mass value="0.11585466541730399" />
            <inertia ixx="4.0924444616882445e-05" iyy="7.006568288089486e-05" izz="4.041124445951843e-05" ixy="-1.0054110693283185e-07" iyz="1.4811257155797803e-07" ixz="8.829348558615142e-06" />
        </inertial>
        <visual name="wrist_1_visual">
            <origin xyz="0.027433858887315282 -0.010090688632958375 0.07569996256195402" rpy="-3.1415926534667786 0.0007586542251124145 1.2331161784418975e-10" />
            <geometry>
                <mesh filename="meshes/wrist_1.stl" scale="0.001 0.001 0.001" />
            </geometry>
        </visual>
        <collision name="wrist_1_collision">
            <origin xyz="0.027433858887315282 -0.010090688632958375 0.07569996256195402" rpy="-3.1415926534667786 0.0007586542251124145 1.2331161784418975e-10" />
            <geometry>
                <mesh filename="meshes/wrist_1.stl" scale="0.001 0.001 0.001" />
            </geometry>
        </collision>
    </link>
    <link name="elbow">
        <inertial>
            <origin xyz="0.018040710501804228 0.0019478439517729917 -0.06237797242409933" rpy="0.0 5.384273822858511e-42 0.0" />
            <mass value="0.3407348467366932" />
            <inertia ixx="0.0004172890688279354" iyy="0.0004424692816513003" izz="9.627918387633638e-05" ixy="-6.352536680366147e-08" iyz="2.585838938287319e-06" ixz="-7.563312832826067e-06" />
        </inertial>
        <visual name="elbow_visual">
            <origin xyz="0.018575303938184597 -0.008291685547433581 -0.00986802758694715" rpy="1.5707963267948941 9.378890893085929e-15 3.1415926535896896" />
            <geometry>
                <mesh filename="meshes/elbow.stl" scale="0.001 0.001 0.001" />
            </geometry>
        </visual>
        <collision name="elbow_collision">
            <origin xyz="0.018575303938184597 -0.008291685547433581 -0.00986802758694715" rpy="1.5707963267948941 9.378890893085929e-15 3.1415926535896896" />
            <geometry>
                <mesh filename="meshes/elbow.stl" scale="0.001 0.001 0.001" />
            </geometry>
        </collision>
    </link>
    <link name="shoulder_lift">
        <inertial>
            <origin xyz="-0.019048152480436488 -0.002487204413744042 0.06764007101107974" rpy="0.0 -0.0 4.701977403289151e-38" />
            <mass value="0.34405090664671173" />
            <inertia ixx="0.000468794075520555" iyy="0.00048660678159251716" izz="8.60833934155829e-05" ixy="-1.148311491676317e-06" iyz="-1.4495429589350659e-05" ixz="-8.758750825438255e-06" />
        </inertial>
        <visual name="shoulder_lift_visual">
            <origin xyz="-0.023923535634807914 -0.11662252790070304 0.04663671163414584" rpy="2.501794501307055e-15 3.456230527471002e-14 0.0007586542252100079" />
            <geometry>
                <mesh filename="meshes/shoulder_lift.stl" scale="0.001 0.001 0.001" />
            </geometry>
        </visual>
        <collision name="shoulder_lift_collision">
            <origin xyz="-0.023923535634807914 -0.11662252790070304 0.04663671163414584" rpy="2.501794501307055e-15 3.456230527471002e-14 0.0007586542252100079" />
            <geometry>
                <mesh filename="meshes/shoulder_lift.stl" scale="0.001 0.001 0.001" />
            </geometry>
        </collision>
    </link>
    <link name="shoulder_pan">
        <inertial>
            <origin xyz="0.018989134905633448 -0.00014114092299989168 -0.03153911547645184" rpy="0.0 -0.0 0.0" />
            <mass value="0.2502336197461597" />
            <inertia ixx="0.00012637117562564913" iyy="0.00016812658172030674" izz="8.320863353444323e-05" ixy="-5.459254475727577e-08" iyz="-5.448473276562819e-07" ixz="-2.0064966517035005e-05" />
        </inertial>
        <visual name="shoulder_pan_visual">
            <origin xyz="-0.09115440191610433 -0.005922736682336927 -0.10184117601351385" rpy="-3.141592078033501 -0.0007586540068865559 1.570796326576611" />
            <geometry>
                <mesh filename="meshes/shoulder_pan.stl" scale="0.001 0.001 0.001" />
            </geometry>
        </visual>
        <collision name="shoulder_pan_collision">
            <origin xyz="-0.09115440191610433 -0.005922736682336927 -0.10184117601351385" rpy="-3.141592078033501 -0.0007586540068865559 1.570796326576611" />
            <geometry>
                <mesh filename="meshes/shoulder_pan.stl" scale="0.001 0.001 0.001" />
            </geometry>
        </collision>
    </link>
    <link name="base_link">
        <inertial>
            <origin xyz="0.04880840731253531 -0.00010333124781364618 0.01395701925933598" rpy="0.0 0.0 0.0" />
            <mass value="0.8122108919622869" />
            <inertia ixx="0.00040099850145791486" iyy="0.0008345308393097832" izz="0.0009101655024927476" ixy="6.247300245825799e-07" iyz="3.222335773697936e-07" ixz="-8.116134374488709e-05" />
        </inertial>
        <visual name="base_link_visual">
            <origin xyz="0.0 0.0 0.0" rpy="0.0 0.0 0.0" />
            <geometry>
                <mesh filename="meshes/base_link.stl" scale="0.001 0.001 0.001" />
            </geometry>
        </visual>
        <collision name="base_link_collision">
            <origin xyz="0.0 0.0 0.0" rpy="0.0 0.0 0.0" />
            <geometry>
                <mesh filename="meshes/base_link.stl" scale="0.001 0.001 0.001" />
            </geometry>
        </collision>
    </link>
    <joint name="base_link_shoulder_pan_joint" type="revolute">
        <origin xyz="0.09891995349082727 -0.00013303822528204945 0.01730000317660415" rpy="3.140833999582907 5.755561299161505e-07 -2.182831748664297e-10" />
        <parent link="base_link" />
        <child link="shoulder_pan" />
        <axis xyz="1e-06 -0.0007590000000000001 1.0000000000000002" />
        <limit lower="-1.832596" upper="1.832596" effort="1000000" velocity="1000000" />
    </joint>
    <joint name="shoulder_pan_shoulder_lift_joint" type="revolute">
        <origin xyz="0.025705489999999998 0.01836629 -0.05461216999999999" rpy="1.5707963267948966 1.0823205351163258e-19 1.57155498102004" />
        <parent link="shoulder_pan" />
        <child link="shoulder_lift" />
        <axis xyz="0.9999992880406866 0.0007590000000000002 -3.4638786191166896e-07" />
        <limit lower="0.0" upper="2.181662" effort="1000000" velocity="1000000" />
    </joint>
    <joint name="shoulder_lift_elbow_joint" type="revolute">
        <origin xyz="-0.03680651674144032 0.025168020000000003 0.10949145809248396" rpy="-3.141592653589793 -3.6944514288095316e-14 -2.4339323090968724e-22" />
        <parent link="shoulder_lift" />
        <child link="elbow" />
        <axis xyz="-1.0000002880403986 3.1928994875519963e-23 -3.4562924470344595e-07" />
        <limit lower="-0.087266" upper="3.054326" effort="1000000" velocity="1000000" />
    </joint>
    <joint name="elbow_wrist_1_joint" type="revolute">
        <origin xyz="-0.00046569601992509926 0.0022157900000000018 -0.1202601813060275" rpy="-3.1415926535897 -3.227344606837599e-14 1.231124669151387e-10" />
        <parent link="elbow" />
        <child link="wrist_1" />
        <axis xyz="-0.9999998631005341 -1.2311237923177398e-10 0.0007583461697307803" />
        <limit lower="-1.832596" upper="1.832596" effort="1000000" velocity="1000000" />
    </joint>
    <joint name="wrist_1_wrist_2_joint" type="revolute">
        <origin xyz="0.02716582734934666 -0.0001989299966499125 0.06031795682590819" rpy="-3.049102007927164 1.5625820319968764 -1.478356089320303" />
        <parent link="wrist_1" />
        <child link="wrist_2" />
        <axis xyz="-0.9999449329225374 0.006662002215913354 -0.008132268196377131" />
        <limit lower="-3.141593" upper="3.141593" effort="1000000" velocity="1000000" />
    </joint>
    <joint name="wrist_2_gripper_joint" type="revolute">
        <origin xyz="-0.017171686526625367 -0.019310353391698003 -0.025579471644208186" rpy="-1.5708498378136646 -0.008179184380179179 0.00075867960162472" />
        <parent link="wrist_2" />
        <child link="gripper" />
        <axis xyz="-0.007420635544791429 -0.0007589999999999999 -0.9999726580742653" />
        <limit lower="0.0" upper="1.745329" effort="1000000" velocity="1000000" />
    </joint>
</robot>